<?xml version="1.0" ?>
<robot name="Stewart_only">

<link name="base_link">
  <inertial>
    <origin xyz="2.3255814076482495e-11 -1.1937212521199739e-11 0.013288962255547656" rpy="0 0 0"/>
    <mass value="13.757667475145922"/>
    <inertia ixx="0.217974" iyy="0.217974" izz="0.434077" ixy="0.0" iyz="0.0" ixz="-0.0"/>
  </inertial>
  <visual>
    <origin xyz="0 0 0" rpy="0 0 0"/>
    <geometry>
      <mesh filename="meshes/base_link.stl" scale="0.001 0.001 0.001"/>
    </geometry>
    <material name="silver"/>
  </visual>
  <collision>
    <origin xyz="0 0 0" rpy="0 0 0"/>
    <geometry>
      <mesh filename="meshes/base_link.stl" scale="0.001 0.001 0.001"/>
    </geometry>
  </collision>
</link>

<link name="X1bottom_1">
  <inertial>
    <origin xyz="0.01275003478154274 0.02208392696742542 -4.072401300903028e-07" rpy="0 0 0"/>
    <mass value="0.015369342112821465"/>
    <inertia ixx="2e-06" iyy="2e-06" izz="3e-06" ixy="-0.0" iyz="-0.0" ixz="1e-06"/>
  </inertial>
  <visual>
    <origin xyz="0.160375 0.15639 -0.064756" rpy="0 0 0"/>
    <geometry>
      <mesh filename="meshes/X1bottom_1.stl" scale="0.001 0.001 0.001"/>
    </geometry>
    <material name="silver"/>
  </visual>
  <collision>
    <origin xyz="0.160375 0.15639 -0.064756" rpy="0 0 0"/>
    <geometry>
      <mesh filename="meshes/X1bottom_1.stl" scale="0.001 0.001 0.001"/>
    </geometry>
  </collision>
</link>

<link name="X6bottom_1">
  <inertial>
    <origin xyz="-0.025500046262033477 -6.640439273453147e-08 -4.0724012444204316e-07" rpy="0 0 0"/>
    <mass value="0.015369342112821434"/>
    <inertia ixx="2e-06" iyy="2e-06" izz="4e-06" ixy="-0.0" iyz="-0.0" ixz="0.0"/>
  </inertial>
  <visual>
    <origin xyz="-0.173125 0.134306 -0.064756" rpy="0 0 0"/>
    <geometry>
      <mesh filename="meshes/X6bottom_1.stl" scale="0.001 0.001 0.001"/>
    </geometry>
    <material name="silver"/>
  </visual>
  <collision>
    <origin xyz="-0.173125 0.134306 -0.064756" rpy="0 0 0"/>
    <geometry>
      <mesh filename="meshes/X6bottom_1.stl" scale="0.001 0.001 0.001"/>
    </geometry>
  </collision>
</link>

<link name="X5bottom_1">
  <inertial>
    <origin xyz="-0.025500046262034837 6.640431129967261e-08 -4.072401355581512e-07" rpy="0 0 0"/>
    <mass value="0.015369342112821526"/>
    <inertia ixx="2e-06" iyy="2e-06" izz="3e-06" ixy="0.0" iyz="1e-06" ixz="-0.0"/>
  </inertial>
  <visual>
    <origin xyz="-0.215625 0.060694 -0.064756" rpy="0 0 0"/>
    <geometry>
      <mesh filename="meshes/X5bottom_1.stl" scale="0.001 0.001 0.001"/>
    </geometry>
    <material name="silver"/>
  </visual>
  <collision>
    <origin xyz="-0.215625 0.060694 -0.064756" rpy="0 0 0"/>
    <geometry>
      <mesh filename="meshes/X5bottom_1.stl" scale="0.001 0.001 0.001"/>
    </geometry>
  </collision>
</link>

<link name="X2bottom_1">
  <inertial>
    <origin xyz="0.012750057742457827 0.022084073032612075 -4.07240119418284e-07" rpy="0 0 0"/>
    <mass value="0.01536934211282146"/>
    <inertia ixx="2e-06" iyy="2e-06" izz="4e-06" ixy="-0.0" iyz="0.0" ixz="-0.0"/>
  </inertial>
  <visual>
    <origin xyz="0.202875 0.082778 -0.064756" rpy="0 0 0"/>
    <geometry>
      <mesh filename="meshes/X2bottom_1.stl" scale="0.001 0.001 0.001"/>
    </geometry>
    <material name="silver"/>
  </visual>
  <collision>
    <origin xyz="0.202875 0.082778 -0.064756" rpy="0 0 0"/>
    <geometry>
      <mesh filename="meshes/X2bottom_1.stl" scale="0.001 0.001 0.001"/>
    </geometry>
  </collision>
</link>

<link name="X4bottom_1">
  <inertial>
    <origin xyz="-0.012750011480423325 0.022083993371774968 -4.0724011886317246e-07" rpy="0 0 0"/>
    <mass value="0.01536934211282148"/>
    <inertia ixx="2e-06" iyy="2e-06" izz="4e-06" ixy="0.0" iyz="0.0" ixz="0.0"/>
  </inertial>
  <visual>
    <origin xyz="-0.05525 -0.172916 -0.064756" rpy="0 0 0"/>
    <geometry>
      <mesh filename="meshes/X4bottom_1.stl" scale="0.001 0.001 0.001"/>
    </geometry>
    <material name="silver"/>
  </visual>
  <collision>
    <origin xyz="-0.05525 -0.172916 -0.064756" rpy="0 0 0"/>
    <geometry>
      <mesh filename="meshes/X4bottom_1.stl" scale="0.001 0.001 0.001"/>
    </geometry>
  </collision>
</link>

<link name="X3bottom_1">
  <inertial>
    <origin xyz="-0.01274998851950876 0.02208400662826518 -4.072401302013251e-07" rpy="0 0 0"/>
    <mass value="0.015369342112821387"/>
    <inertia ixx="2e-06" iyy="2e-06" izz="3e-06" ixy="0.0" iyz="-0.0" ixz="-1e-06"/>
  </inertial>
  <visual>
    <origin xyz="0.02975 -0.172916 -0.064756" rpy="0 0 0"/>
    <geometry>
      <mesh filename="meshes/X3bottom_1.stl" scale="0.001 0.001 0.001"/>
    </geometry>
    <material name="silver"/>
  </visual>
  <collision>
    <origin xyz="0.02975 -0.172916 -0.064756" rpy="0 0 0"/>
    <geometry>
      <mesh filename="meshes/X3bottom_1.stl" scale="0.001 0.001 0.001"/>
    </geometry>
  </collision>
</link>

<link name="cylinder6_1">
  <inertial>
    <origin xyz="-0.04936437063232299 -0.05308323327299884 0.11048411160322401" rpy="0 0 0"/>
    <mass value="1.083459541527402"/>
    <inertia ixx="0.003927" iyy="0.004328" izz="0.001198" ixy="-0.000339" iyz="0.0008" ixz="0.001409"/>
  </inertial>
  <visual>
    <origin xyz="-0.147625 0.109271 -0.070782" rpy="0 0 0"/>
    <geometry>
      <mesh filename="meshes/cylinder6_1.stl" scale="0.001 0.001 0.001"/>
    </geometry>
    <material name="silver"/>
  </visual>
  <collision>
    <origin xyz="-0.147625 0.109271 -0.070782" rpy="0 0 0"/>
    <geometry>
      <mesh filename="meshes/cylinder6_1.stl" scale="0.001 0.001 0.001"/>
    </geometry>
  </collision>
</link>

<link name="cylinder5_1">
  <inertial>
    <origin xyz="-0.0005391942218705703 0.07871427363633557 0.1061369773985035" rpy="0 0 0"/>
    <mass value="1.0834593359661664"/>
    <inertia ixx="0.004524" iyy="0.003769" izz="0.001161" ixy="7e-06" iyz="-0.00159" ixz="1.5e-05"/>
  </inertial>
  <visual>
    <origin xyz="-0.190125 0.083969 -0.07577" rpy="0 0 0"/>
    <geometry>
      <mesh filename="meshes/cylinder5_1.stl" scale="0.001 0.001 0.001"/>
    </geometry>
    <material name="silver"/>
  </visual>
  <collision>
    <origin xyz="-0.190125 0.083969 -0.07577" rpy="0 0 0"/>
    <geometry>
      <mesh filename="meshes/cylinder5_1.stl" scale="0.001 0.001 0.001"/>
    </geometry>
  </collision>
</link>

<link name="cylinder1_1">
  <inertial>
    <origin xyz="0.02729482532372013 -0.016329820457659128 0.12825573678482122" rpy="0 0 0"/>
    <mass value="1.0834595971642158"/>
    <inertia ixx="0.00397" iyy="0.004331" izz="0.001152" ixy="0.000326" iyz="0.000804" ixz="-0.001364"/>
  </inertial>
  <visual>
    <origin xyz="0.127441 0.145959 -0.053807" rpy="0 0 0"/>
    <geometry>
      <mesh filename="meshes/cylinder1_1.stl" scale="0.001 0.001 0.001"/>
    </geometry>
    <material name="silver"/>
  </visual>
  <collision>
    <origin xyz="0.127441 0.145959 -0.053807" rpy="0 0 0"/>
    <geometry>
      <mesh filename="meshes/cylinder1_1.stl" scale="0.001 0.001 0.001"/>
    </geometry>
  </collision>
</link>

<link name="cylinder2_1">
  <inertial>
    <origin xyz="-0.022200241098937062 0.0686570498281845 0.11070095070557585" rpy="0 0 0"/>
    <mass value="1.083459599703058"/>
    <inertia ixx="0.004522" iyy="0.003751" izz="0.001181" ixy="8e-06" iyz="-0.001607" ixz="1.5e-05"/>
  </inertial>
  <visual>
    <origin xyz="0.168462 0.073201 -0.070867" rpy="0 0 0"/>
    <geometry>
      <mesh filename="meshes/cylinder2_1.stl" scale="0.001 0.001 0.001"/>
    </geometry>
    <material name="silver"/>
  </visual>
  <collision>
    <origin xyz="0.168462 0.073201 -0.070867" rpy="0 0 0"/>
    <geometry>
      <mesh filename="meshes/cylinder2_1.stl" scale="0.001 0.001 0.001"/>
    </geometry>
  </collision>
</link>

<link name="cylinder3_1">
  <inertial>
    <origin xyz="-0.06886834961262803 -0.039309713367164906 0.10570290713184599" rpy="0 0 0"/>
    <mass value="1.0834597856232793"/>
    <inertia ixx="0.00394" iyy="0.004335" izz="0.001178" ixy="-0.000332" iyz="0.000792" ixz="0.001395"/>
  </inertial>
  <visual>
    <origin xyz="0.022396 -0.206607 -0.075898" rpy="0 0 0"/>
    <geometry>
      <mesh filename="meshes/cylinder3_1.stl" scale="0.001 0.001 0.001"/>
    </geometry>
    <material name="silver"/>
  </visual>
  <collision>
    <origin xyz="0.022396 -0.206607 -0.075898" rpy="0 0 0"/>
    <geometry>
      <mesh filename="meshes/cylinder3_1.stl" scale="0.001 0.001 0.001"/>
    </geometry>
  </collision>
</link>

<link name="cylinder4_1">
  <inertial>
    <origin xyz="0.026240778221358257 -0.04079286613222788 0.12291755682136629" rpy="0 0 0"/>
    <mass value="1.0834593902746585"/>
    <inertia ixx="0.003958" iyy="0.004327" izz="0.001167" ixy="0.000331" iyz="0.000811" ixz="-0.001375"/>
  </inertial>
  <visual>
    <origin xyz="-0.064213 -0.207536 -0.058886" rpy="0 0 0"/>
    <geometry>
      <mesh filename="meshes/cylinder4_1.stl" scale="0.001 0.001 0.001"/>
    </geometry>
    <material name="silver"/>
  </visual>
  <collision>
    <origin xyz="-0.064213 -0.207536 -0.058886" rpy="0 0 0"/>
    <geometry>
      <mesh filename="meshes/cylinder4_1.stl" scale="0.001 0.001 0.001"/>
    </geometry>
  </collision>
</link>

<link name="rod1_1">
  <inertial>
    <origin xyz="-0.0363119660977582 0.02140153438053846 -0.08971792919781321" rpy="0 0 0"/>
    <mass value="0.2833716573537993"/>
    <inertia ixx="0.000826" iyy="0.000908" izz="0.000184" ixy="7.4e-05" iyz="0.000183" ixz="-0.000311"/>
  </inertial>
  <visual>
    <origin xyz="0.059705 0.186124 -0.281983" rpy="0 0 0"/>
    <geometry>
      <mesh filename="meshes/rod1_1.stl" scale="0.001 0.001 0.001"/>
    </geometry>
    <material name="silver"/>
  </visual>
  <collision>
    <origin xyz="0.059705 0.186124 -0.281983" rpy="0 0 0"/>
    <geometry>
      <mesh filename="meshes/rod1_1.stl" scale="0.001 0.001 0.001"/>
    </geometry>
  </collision>
</link>

<link name="rod2_1">
  <inertial>
    <origin xyz="0.00040765407980625223 -0.0425838018149945 -0.08859030306524057" rpy="0 0 0"/>
    <mass value="0.2833716573537998"/>
    <inertia ixx="0.000952" iyy="0.000776" izz="0.00019" ixy="2e-06" iyz="-0.000366" ixz="4e-06"/>
  </inertial>
  <visual>
    <origin xyz="0.19112 -0.043283 -0.281066" rpy="0 0 0"/>
    <geometry>
      <mesh filename="meshes/rod2_1.stl" scale="0.001 0.001 0.001"/>
    </geometry>
    <material name="silver"/>
  </visual>
  <collision>
    <origin xyz="0.19112 -0.043283 -0.281066" rpy="0 0 0"/>
    <geometry>
      <mesh filename="meshes/rod2_1.stl" scale="0.001 0.001 0.001"/>
    </geometry>
  </collision>
</link>

<link name="rod3_1">
  <inertial>
    <origin xyz="0.03698945499219167 0.021013065163081268 -0.08863127807602841" rpy="0 0 0"/>
    <mass value="0.2833716573537997"/>
    <inertia ixx="0.000819" iyy="0.000909" izz="0.00019" ixy="-7.5e-05" iyz="0.000181" ixz="0.000318"/>
  </inertial>
  <visual>
    <origin xyz="0.132801 -0.143701 -0.281128" rpy="0 0 0"/>
    <geometry>
      <mesh filename="meshes/rod3_1.stl" scale="0.001 0.001 0.001"/>
    </geometry>
    <material name="silver"/>
  </visual>
  <collision>
    <origin xyz="0.132801 -0.143701 -0.281128" rpy="0 0 0"/>
    <geometry>
      <mesh filename="meshes/rod3_1.stl" scale="0.001 0.001 0.001"/>
    </geometry>
  </collision>
</link>

<link name="rod4_1">
  <inertial>
    <origin xyz="-0.03634169091616525 0.02141475285206132 -0.08870439058730761" rpy="0 0 0"/>
    <mass value="0.28337165735379954"/>
    <inertia ixx="0.000823" iyy="0.000907" izz="0.000187" ixy="7.6e-05" iyz="0.000185" ixz="-0.000313"/>
  </inertial>
  <visual>
    <origin xyz="-0.1313 -0.142674 -0.281503" rpy="0 0 0"/>
    <geometry>
      <mesh filename="meshes/rod4_1.stl" scale="0.001 0.001 0.001"/>
    </geometry>
    <material name="silver"/>
  </visual>
  <collision>
    <origin xyz="-0.1313 -0.142674 -0.281503" rpy="0 0 0"/>
    <geometry>
      <mesh filename="meshes/rod4_1.stl" scale="0.001 0.001 0.001"/>
    </geometry>
  </collision>
</link>

<link name="rod5_1">
  <inertial>
    <origin xyz="0.00040876764670991217 -0.04207635461802559 -0.0889138885284477" rpy="0 0 0"/>
    <mass value="0.28337165735379943"/>
    <inertia ixx="0.000952" iyy="0.00078" izz="0.000186" ixy="2e-06" iyz="-0.000362" ixz="4e-06"/>
  </inertial>
  <visual>
    <origin xyz="-0.189127 -0.041967 -0.281694" rpy="0 0 0"/>
    <geometry>
      <mesh filename="meshes/rod5_1.stl" scale="0.001 0.001 0.001"/>
    </geometry>
    <material name="silver"/>
  </visual>
  <collision>
    <origin xyz="-0.189127 -0.041967 -0.281694" rpy="0 0 0"/>
    <geometry>
      <mesh filename="meshes/rod5_1.stl" scale="0.001 0.001 0.001"/>
    </geometry>
  </collision>
</link>

<link name="rod6_1">
  <inertial>
    <origin xyz="0.037383047951974016 0.021240492770698255 -0.08823245154948317" rpy="0 0 0"/>
    <mass value="0.2833716573537994"/>
    <inertia ixx="0.000816" iyy="0.000908" izz="0.000194" ixy="-7.7e-05" iyz="0.000182" ixz="0.000321"/>
  </inertial>
  <visual>
    <origin xyz="-0.056213 0.186245 -0.280508" rpy="0 0 0"/>
    <geometry>
      <mesh filename="meshes/rod6_1.stl" scale="0.001 0.001 0.001"/>
    </geometry>
    <material name="silver"/>
  </visual>
  <collision>
    <origin xyz="-0.056213 0.186245 -0.280508" rpy="0 0 0"/>
    <geometry>
      <mesh filename="meshes/rod6_1.stl" scale="0.001 0.001 0.001"/>
    </geometry>
  </collision>
</link>

<link name="piston1_1">
  <inertial>
    <origin xyz="0.003260719383217446 -0.00192086747489148 0.008055557047720485" rpy="0 0 0"/>
    <mass value="0.08578443099201062"/>
    <inertia ixx="1.9e-05" iyy="2e-05" izz="2.7e-05" ixy="-2e-06" iyz="-1e-06" ixz="3e-06"/>
  </inertial>
  <visual>
    <origin xyz="0.059384 0.186313 -0.282774" rpy="0 0 0"/>
    <geometry>
      <mesh filename="meshes/piston1_1.stl" scale="0.001 0.001 0.001"/>
    </geometry>
    <material name="silver"/>
  </visual>
  <collision>
    <origin xyz="0.059384 0.186313 -0.282774" rpy="0 0 0"/>
    <geometry>
      <mesh filename="meshes/piston1_1.stl" scale="0.001 0.001 0.001"/>
    </geometry>
  </collision>
</link>

<link name="piston2_1">
  <inertial>
    <origin xyz="-3.6747621563193444e-05 0.00385505605944253 0.008022004528809967" rpy="0 0 0"/>
    <mass value="0.08578414622058635"/>
    <inertia ixx="2e-05" iyy="1.9e-05" izz="2.6e-05" ixy="-0.0" iyz="4e-06" ixz="-0.0"/>
  </inertial>
  <visual>
    <origin xyz="0.191127 -0.044022 -0.282603" rpy="0 0 0"/>
    <geometry>
      <mesh filename="meshes/piston2_1.stl" scale="0.001 0.001 0.001"/>
    </geometry>
    <material name="silver"/>
  </visual>
  <collision>
    <origin xyz="0.191127 -0.044022 -0.282603" rpy="0 0 0"/>
    <geometry>
      <mesh filename="meshes/piston2_1.stl" scale="0.001 0.001 0.001"/>
    </geometry>
  </collision>
</link>

<link name="piston3_1">
  <inertial>
    <origin xyz="-0.003348642128974705 -0.001903364795347251 0.008023117770736776" rpy="0 0 0"/>
    <mass value="0.08578406699699544"/>
    <inertia ixx="2.1e-05" iyy="1.8e-05" izz="2.7e-05" ixy="1e-06" iyz="-2e-06" ixz="-3e-06"/>
  </inertial>
  <visual>
    <origin xyz="0.133436 -0.14334 -0.28265" rpy="0 0 0"/>
    <geometry>
      <mesh filename="meshes/piston3_1.stl" scale="0.001 0.001 0.001"/>
    </geometry>
    <material name="silver"/>
  </visual>
  <collision>
    <origin xyz="0.133436 -0.14334 -0.28265" rpy="0 0 0"/>
    <geometry>
      <mesh filename="meshes/piston3_1.stl" scale="0.001 0.001 0.001"/>
    </geometry>
  </collision>
</link>

<link name="piston6_1">
  <inertial>
    <origin xyz="-0.0033895159992465007 -0.0019258741237710708 0.008001250404574778" rpy="0 0 0"/>
    <mass value="0.08578421036573615"/>
    <inertia ixx="1.9e-05" iyy="2e-05" izz="2.6e-05" ixy="-0.0" iyz="-2e-06" ixz="-4e-06"/>
  </inertial>
  <visual>
    <origin xyz="-0.055509 0.186645 -0.28217" rpy="0 0 0"/>
    <geometry>
      <mesh filename="meshes/piston6_1.stl" scale="0.001 0.001 0.001"/>
    </geometry>
    <material name="silver"/>
  </visual>
  <collision>
    <origin xyz="-0.055509 0.186645 -0.28217" rpy="0 0 0"/>
    <geometry>
      <mesh filename="meshes/piston6_1.stl" scale="0.001 0.001 0.001"/>
    </geometry>
  </collision>
</link>

<link name="piston5_1">
  <inertial>
    <origin xyz="-3.796842945222312e-05 0.003807538312228631 0.00804468407875164" rpy="0 0 0"/>
    <mass value="0.08578423958035213"/>
    <inertia ixx="1.8e-05" iyy="2.1e-05" izz="2.7e-05" ixy="1e-06" iyz="4e-06" ixz="-1e-06"/>
  </inertial>
  <visual>
    <origin xyz="-0.18912 -0.042665 -0.283169" rpy="0 0 0"/>
    <geometry>
      <mesh filename="meshes/piston5_1.stl" scale="0.001 0.001 0.001"/>
    </geometry>
    <material name="silver"/>
  </visual>
  <collision>
    <origin xyz="-0.18912 -0.042665 -0.283169" rpy="0 0 0"/>
    <geometry>
      <mesh filename="meshes/piston5_1.stl" scale="0.001 0.001 0.001"/>
    </geometry>
  </collision>
</link>

<link name="piston4_1">
  <inertial>
    <origin xyz="0.0032926577328955264 -0.0019400363790381403 0.008037838079846149" rpy="0 0 0"/>
    <mass value="0.08578412180440002"/>
    <inertia ixx="1.9e-05" iyy="2e-05" izz="2.6e-05" ixy="0.0" iyz="-2e-06" ixz="4e-06"/>
  </inertial>
  <visual>
    <origin xyz="-0.131957 -0.142287 -0.283108" rpy="0 0 0"/>
    <geometry>
      <mesh filename="meshes/piston4_1.stl" scale="0.001 0.001 0.001"/>
    </geometry>
    <material name="silver"/>
  </visual>
  <collision>
    <origin xyz="-0.131957 -0.142287 -0.283108" rpy="0 0 0"/>
    <geometry>
      <mesh filename="meshes/piston4_1.stl" scale="0.001 0.001 0.001"/>
    </geometry>
  </collision>
</link>

<link name="X6top_1">
  <inertial>
    <origin xyz="-0.019893465178586138 -0.011389699074627252 -0.011170064502357191" rpy="0 0 0"/>
    <mass value="0.015369342112822157"/>
    <inertia ixx="2e-06" iyy="2e-06" izz="3e-06" ixy="0.0" iyz="-0.0" ixz="-1e-06"/>
  </inertial>
  <visual>
    <origin xyz="-0.060165 0.183913 -0.329303" rpy="0 0 0"/>
    <geometry>
      <mesh filename="meshes/X6top_1.stl" scale="0.001 0.001 0.001"/>
    </geometry>
    <material name="silver"/>
  </visual>
  <collision>
    <origin xyz="-0.060165 0.183913 -0.329303" rpy="0 0 0"/>
    <geometry>
      <mesh filename="meshes/X6top_1.stl" scale="0.001 0.001 0.001"/>
    </geometry>
  </collision>
</link>

<link name="X1top_1">
  <inertial>
    <origin xyz="-0.021561342143433596 -0.012322044617543215 0.0057870217842545535" rpy="0 0 0"/>
    <mass value="0.015369342112821583"/>
    <inertia ixx="2e-06" iyy="2e-06" izz="4e-06" ixy="0.0" iyz="0.0" ixz="0.0"/>
  </inertial>
  <visual>
    <origin xyz="0.023168 0.182628 -0.313196" rpy="0 0 0"/>
    <geometry>
      <mesh filename="meshes/X1top_1.stl" scale="0.001 0.001 0.001"/>
    </geometry>
    <material name="silver"/>
  </visual>
  <collision>
    <origin xyz="0.023168 0.182628 -0.313196" rpy="0 0 0"/>
    <geometry>
      <mesh filename="meshes/X1top_1.stl" scale="0.001 0.001 0.001"/>
    </geometry>
  </collision>
</link>

<link name="X4top_1">
  <inertial>
    <origin xyz="-0.019898963252462376 0.01159097769330164 0.010950537929455939" rpy="0 0 0"/>
    <mass value="0.015369342112821675"/>
    <inertia ixx="2e-06" iyy="2e-06" izz="3e-06" ixy="-0.0" iyz="-0.0" ixz="1e-06"/>
  </inertial>
  <visual>
    <origin xyz="-0.166658 -0.121974 -0.308286" rpy="0 0 0"/>
    <geometry>
      <mesh filename="meshes/X4top_1.stl" scale="0.001 0.001 0.001"/>
    </geometry>
    <material name="silver"/>
  </visual>
  <collision>
    <origin xyz="-0.166658 -0.121974 -0.308286" rpy="0 0 0"/>
    <geometry>
      <mesh filename="meshes/X4top_1.stl" scale="0.001 0.001 0.001"/>
    </geometry>
  </collision>
</link>

<link name="X5top_1">
  <inertial>
    <origin xyz="-0.021408625059915254 0.012483273926971863 -0.00600622023844799" rpy="0 0 0"/>
    <mass value="0.015369342112821502"/>
    <inertia ixx="2e-06" iyy="2e-06" izz="4e-06" ixy="-0.0" iyz="0.0" ixz="-0.0"/>
  </inertial>
  <visual>
    <origin xyz="-0.210362 -0.047294 -0.325336" rpy="0 0 0"/>
    <geometry>
      <mesh filename="meshes/X5top_1.stl" scale="0.001 0.001 0.001"/>
    </geometry>
    <material name="silver"/>
  </visual>
  <collision>
    <origin xyz="-0.210362 -0.047294 -0.325336" rpy="0 0 0"/>
    <geometry>
      <mesh filename="meshes/X5top_1.stl" scale="0.001 0.001 0.001"/>
    </geometry>
  </collision>
</link>

<link name="UJ1_1">
  <inertial>
    <origin xyz="-0.012837420559777761 0.022361614937716018 0.030940336511158628" rpy="0 0 0"/>
    <mass value="0.08446437141832064"/>
    <inertia ixx="1.9e-05" iyy="1.7e-05" izz="2.8e-05" ixy="1e-06" iyz="0.0" ixz="-0.0"/>
  </inertial>
  <visual>
    <origin xyz="0.031947 0.217303 -0.319011" rpy="0 0 0"/>
    <geometry>
      <mesh filename="meshes/UJ1_1.stl" scale="0.001 0.001 0.001"/>
    </geometry>
    <material name="silver"/>
  </visual>
  <collision>
    <origin xyz="0.031947 0.217303 -0.319011" rpy="0 0 0"/>
    <geometry>
      <mesh filename="meshes/UJ1_1.stl" scale="0.001 0.001 0.001"/>
    </geometry>
  </collision>
</link>

<link name="UJ6_1">
  <inertial>
    <origin xyz="-0.012837553348221412 0.022360664031001204 0.03148874152476355" rpy="0 0 0"/>
    <mass value="0.089765809021081"/>
    <inertia ixx="2e-05" iyy="1.9e-05" izz="3e-05" ixy="1e-06" iyz="0.0" ixz="-0.0"/>
  </inertial>
  <visual>
    <origin xyz="-0.053054 0.217656 -0.318161" rpy="0 0 0"/>
    <geometry>
      <mesh filename="meshes/UJ6_1.stl" scale="0.001 0.001 0.001"/>
    </geometry>
    <material name="silver"/>
  </visual>
  <collision>
    <origin xyz="-0.053054 0.217656 -0.318161" rpy="0 0 0"/>
    <geometry>
      <mesh filename="meshes/UJ6_1.stl" scale="0.001 0.001 0.001"/>
    </geometry>
  </collision>
</link>

<link name="UJ5_1">
  <inertial>
    <origin xyz="-0.013022605591247183 -0.022239603834112852 0.030951095080068047" rpy="0 0 0"/>
    <mass value="0.08446437135496666"/>
    <inertia ixx="1.9e-05" iyy="1.7e-05" izz="2.8e-05" ixy="-1e-06" iyz="-0.0" ixz="-0.0"/>
  </inertial>
  <visual>
    <origin xyz="-0.201921 -0.082024 -0.319347" rpy="0 0 0"/>
    <geometry>
      <mesh filename="meshes/UJ5_1.stl" scale="0.001 0.001 0.001"/>
    </geometry>
    <material name="silver"/>
  </visual>
  <collision>
    <origin xyz="-0.201921 -0.082024 -0.319347" rpy="0 0 0"/>
    <geometry>
      <mesh filename="meshes/UJ5_1.stl" scale="0.001 0.001 0.001"/>
    </geometry>
  </collision>
</link>

<link name="UJ4_1">
  <inertial>
    <origin xyz="-0.013021154103656923 -0.022238306259387025 0.030950854232405622" rpy="0 0 0"/>
    <mass value="0.08446437135502799"/>
    <inertia ixx="1.9e-05" iyy="1.7e-05" izz="2.8e-05" ixy="-1e-06" iyz="0.0" ixz="-0.0"/>
  </inertial>
  <visual>
    <origin xyz="-0.159726 -0.155812 -0.319254" rpy="0 0 0"/>
    <geometry>
      <mesh filename="meshes/UJ4_1.stl" scale="0.001 0.001 0.001"/>
    </geometry>
    <material name="silver"/>
  </visual>
  <collision>
    <origin xyz="-0.159726 -0.155812 -0.319254" rpy="0 0 0"/>
    <geometry>
      <mesh filename="meshes/UJ4_1.stl" scale="0.001 0.001 0.001"/>
    </geometry>
  </collision>
</link>

<link name="X3top_1">
  <inertial>
    <origin xyz="-9.28858073003247e-05 -0.024803007598659416 -0.0059191862387001914" rpy="0 0 0"/>
    <mass value="0.015369342112821555"/>
    <inertia ixx="2e-06" iyy="2e-06" izz="4e-06" ixy="0.0" iyz="-0.0" ixz="-0.0"/>
  </inertial>
  <visual>
    <origin xyz="0.148395 -0.159592 -0.324635" rpy="0 0 0"/>
    <geometry>
      <mesh filename="meshes/X3top_1.stl" scale="0.001 0.001 0.001"/>
    </geometry>
    <material name="silver"/>
  </visual>
  <collision>
    <origin xyz="0.148395 -0.159592 -0.324635" rpy="0 0 0"/>
    <geometry>
      <mesh filename="meshes/X3top_1.stl" scale="0.001 0.001 0.001"/>
    </geometry>
  </collision>
</link>

<link name="UJ3_1">
  <inertial>
    <origin xyz="-0.025803583885874712 0.00011496804616903389 0.030923131071302012" rpy="0 0 0"/>
    <mass value="0.08446437149876586"/>
    <inertia ixx="1.7e-05" iyy="1.9e-05" izz="2.8e-05" ixy="0.0" iyz="0.0" ixz="-0.0"/>
  </inertial>
  <visual>
    <origin xyz="0.122738 -0.134682 -0.318761" rpy="0 0 0"/>
    <geometry>
      <mesh filename="meshes/UJ3_1.stl" scale="0.001 0.001 0.001"/>
    </geometry>
    <material name="silver"/>
  </visual>
  <collision>
    <origin xyz="0.122738 -0.134682 -0.318761" rpy="0 0 0"/>
    <geometry>
      <mesh filename="meshes/UJ3_1.stl" scale="0.001 0.001 0.001"/>
    </geometry>
  </collision>
</link>

<link name="X2top_1">
  <inertial>
    <origin xyz="-0.00011466195212661567 -0.022982312625086758 0.011047143465836295" rpy="0 0 0"/>
    <mass value="0.015369342112821335"/>
    <inertia ixx="2e-06" iyy="2e-06" izz="3e-06" ixy="0.0" iyz="1e-06" ixz="0.0"/>
  </inertial>
  <visual>
    <origin xyz="0.191178 -0.084336 -0.307612" rpy="0 0 0"/>
    <geometry>
      <mesh filename="meshes/X2top_1.stl" scale="0.001 0.001 0.001"/>
    </geometry>
    <material name="silver"/>
  </visual>
  <collision>
    <origin xyz="0.191178 -0.084336 -0.307612" rpy="0 0 0"/>
    <geometry>
      <mesh filename="meshes/X2top_1.stl" scale="0.001 0.001 0.001"/>
    </geometry>
  </collision>
</link>

<link name="UJ2_1">
  <inertial>
    <origin xyz="0.025693864744190664 -9.844998390469428e-05 0.031013457675736433" rpy="0 0 0"/>
    <mass value="0.08446437149882718"/>
    <inertia ixx="1.7e-05" iyy="1.9e-05" izz="2.8e-05" ixy="0.0" iyz="0.0" ixz="-0.0"/>
  </inertial>
  <visual>
    <origin xyz="0.217042 -0.06146 -0.318614" rpy="0 0 0"/>
    <geometry>
      <mesh filename="meshes/UJ2_1.stl" scale="0.001 0.001 0.001"/>
    </geometry>
    <material name="silver"/>
  </visual>
  <collision>
    <origin xyz="0.217042 -0.06146 -0.318614" rpy="0 0 0"/>
    <geometry>
      <mesh filename="meshes/UJ2_1.stl" scale="0.001 0.001 0.001"/>
    </geometry>
  </collision>
</link>

<link name="TOP_1">
  <inertial>
    <origin xyz="0.04328903595379507 0.19482493931376896 0.010581548215173764" rpy="0 0 0"/>
    <mass value="13.182708498536908"/>
    <inertia ixx="0.206266" iyy="0.206265" izz="0.411168" ixy="-0.0" iyz="5.2e-05" ixz="-0.000361"/>
  </inertial>
  <visual>
    <origin xyz="0.044799 0.19494 -0.358739" rpy="0 0 0"/>
    <geometry>
      <mesh filename="meshes/TOP_1.stl" scale="0.001 0.001 0.001"/>
    </geometry>
    <material name="silver"/>
  </visual>
  <collision>
    <origin xyz="0.044799 0.19494 -0.358739" rpy="0 0 0"/>
    <geometry>
      <mesh filename="meshes/TOP_1.stl" scale="0.001 0.001 0.001"/>
    </geometry>
  </collision>
</link>

<joint name="r_xb1" type="revolute">
  <origin xyz="-0.160375 -0.15639 0.064756" rpy="0 0 0"/>
  <parent link="base_link"/>
  <child link="X1bottom_1"/>
  <axis xyz="-0.5 -0.866025 -0.0"/>
  <limit upper="0.785398" lower="-0.785398" effort="100" velocity="100"/>
</joint>

<joint name="r_xb6" type="revolute">
  <origin xyz="0.173125 -0.134306 0.064756" rpy="0 0 0"/>
  <parent link="base_link"/>
  <child link="X6bottom_1"/>
  <axis xyz="1.0 -0.0 0.0"/>
  <limit upper="0.785398" lower="-0.785398" effort="100" velocity="100"/>
</joint>

<joint name="r_xb5" type="revolute">
  <origin xyz="0.215625 -0.060694 0.064756" rpy="0 0 0"/>
  <parent link="base_link"/>
  <child link="X5bottom_1"/>
  <axis xyz="1.0 -0.0 -0.0"/>
  <limit upper="0.785398" lower="-0.785398" effort="100" velocity="100"/>
</joint>

<joint name="r_xb2" type="revolute">
  <origin xyz="-0.202875 -0.082778 0.064756" rpy="0 0 0"/>
  <parent link="base_link"/>
  <child link="X2bottom_1"/>
  <axis xyz="-0.5 -0.866025 0.0"/>
  <limit upper="0.785398" lower="-0.785398" effort="100" velocity="100"/>
</joint>

<joint name="r_xb4" type="revolute">
  <origin xyz="0.05525 0.172916 0.064756" rpy="0 0 0"/>
  <parent link="base_link"/>
  <child link="X4bottom_1"/>
  <axis xyz="0.5 -0.866025 -0.0"/>
  <limit upper="0.785398" lower="-0.785398" effort="100" velocity="100"/>
</joint>

<joint name="r_xb3" type="revolute">
  <origin xyz="-0.02975 0.172916 0.064756" rpy="0 0 0"/>
  <parent link="base_link"/>
  <child link="X3bottom_1"/>
  <axis xyz="0.5 -0.866025 0.0"/>
  <limit upper="0.785398" lower="-0.785398" effort="100" velocity="100"/>
</joint>

<joint name="r_xb_rod6" type="revolute">
  <origin xyz="-0.0255 0.025035 0.006026" rpy="0 0 0"/>
  <parent link="X6bottom_1"/>
  <child link="cylinder6_1"/>
  <axis xyz="0.0 0.972225 0.234048"/>
  <limit upper="0.785398" lower="-0.785398" effort="100" velocity="100"/>
</joint>

<joint name="r_xb_rod5" type="revolute">
  <origin xyz="-0.0255 -0.023275 0.011014" rpy="0 0 0"/>
  <parent link="X5bottom_1"/>
  <child link="cylinder5_1"/>
  <axis xyz="-0.0 -0.903898 0.427748"/>
  <limit upper="0.785398" lower="-0.785398" effort="100" velocity="100"/>
</joint>

<joint name="r_xb_rod1" type="revolute">
  <origin xyz="0.032934 0.010431 -0.010949" rpy="0 0 0"/>
  <parent link="X1bottom_1"/>
  <child link="cylinder1_1"/>
  <axis xyz="0.783838 -0.452549 -0.425202"/>
  <limit upper="0.785398" lower="-0.785398" effort="100" velocity="100"/>
</joint>

<joint name="r_xb_rod2" type="revolute">
  <origin xyz="0.034413 0.009577 0.006111" rpy="0 0 0"/>
  <parent link="X2bottom_1"/>
  <child link="cylinder2_1"/>
  <axis xyz="0.841279 -0.485713 0.237344"/>
  <limit upper="0.785398" lower="-0.785398" effort="100" velocity="100"/>
</joint>

<joint name="r_xb_rod3" type="revolute">
  <origin xyz="0.007354 0.033691 0.011142" rpy="0 0 0"/>
  <parent link="X3bottom_1"/>
  <child link="cylinder3_1"/>
  <axis xyz="0.78075 0.450766 0.43271"/>
  <limit upper="0.785398" lower="-0.785398" effort="100" velocity="100"/>
</joint>

<joint name="r_xb_rod4" type="revolute">
  <origin xyz="0.008963 0.03462 -0.00587" rpy="0 0 0"/>
  <parent link="X4bottom_1"/>
  <child link="cylinder4_1"/>
  <axis xyz="0.843228 0.486838 -0.227936"/>
  <limit upper="0.785398" lower="-0.785398" effort="100" velocity="100"/>
</joint>

<joint name="s1" type="prismatic">
  <origin xyz="0.067736 -0.040165 0.228176" rpy="0 0 0"/>
  <parent link="cylinder1_1"/>
  <child link="rod1_1"/>
  <axis xyz="0.366326 -0.215903 0.905092"/>
  <limit upper="0.19" lower="0.0" effort="100" velocity="100"/>
</joint>

<joint name="s2" type="prismatic">
  <origin xyz="-0.022658 0.116484 0.210199" rpy="0 0 0"/>
  <parent link="cylinder2_1"/>
  <child link="rod2_1"/>
  <axis xyz="-0.004145 0.433229 0.901274"/>
  <limit upper="0.19" lower="0.0" effort="100" velocity="100"/>
</joint>

<joint name="s3" type="prismatic">
  <origin xyz="-0.110405 -0.062906 0.20523" rpy="0 0 0"/>
  <parent link="cylinder3_1"/>
  <child link="rod3_1"/>
  <axis xyz="-0.376245 -0.213742 0.901529"/>
  <limit upper="0.19" lower="0.0" effort="100" velocity="100"/>
</joint>

<joint name="s4" type="prismatic">
  <origin xyz="0.067087 -0.064862 0.222617" rpy="0 0 0"/>
  <parent link="cylinder4_1"/>
  <child link="rod4_1"/>
  <axis xyz="0.36999 -0.218018 0.903092"/>
  <limit upper="0.19" lower="0.0" effort="100" velocity="100"/>
</joint>

<joint name="s5" type="prismatic">
  <origin xyz="-0.000998 0.125936 0.205924" rpy="0 0 0"/>
  <parent link="cylinder5_1"/>
  <child link="rod5_1"/>
  <axis xyz="-0.00416 0.427745 0.90389"/>
  <limit upper="0.19" lower="0.0" effort="100" velocity="100"/>
</joint>

<joint name="s6" type="prismatic">
  <origin xyz="-0.091412 -0.076974 0.209726" rpy="0 0 0"/>
  <parent link="cylinder6_1"/>
  <child link="rod6_1"/>
  <axis xyz="-0.380874 -0.216407 0.898945"/>
  <limit upper="0.19" lower="0.0" effort="100" velocity="100"/>
</joint>

<joint name="r_rod1" type="revolute">
  <origin xyz="0.000321 -0.000189 0.000791" rpy="0 0 0"/>
  <parent link="rod1_1"/>
  <child link="piston1_1"/>
  <axis xyz="0.366326 -0.215903 0.905092"/>
  <limit upper="6.283185" lower="0.0" effort="100" velocity="100"/>
</joint>

<joint name="r_rod2" type="revolute">
  <origin xyz="-7e-06 0.000739 0.001537" rpy="0 0 0"/>
  <parent link="rod2_1"/>
  <child link="piston2_1"/>
  <axis xyz="-0.004145 0.433229 0.901274"/>
  <limit upper="6.283185" lower="0.0" effort="100" velocity="100"/>
</joint>

<joint name="r_rod3" type="revolute">
  <origin xyz="-0.000635 -0.000361 0.001522" rpy="0 0 0"/>
  <parent link="rod3_1"/>
  <child link="piston3_1"/>
  <axis xyz="-0.376245 -0.213742 0.901529"/>
  <limit upper="6.283185" lower="0.0" effort="100" velocity="100"/>
</joint>

<joint name="r_rod6" type="revolute">
  <origin xyz="-0.000704 -0.0004 0.001662" rpy="0 0 0"/>
  <parent link="rod6_1"/>
  <child link="piston6_1"/>
  <axis xyz="-0.380874 -0.216407 0.898945"/>
  <limit upper="6.283185" lower="0.0" effort="100" velocity="100"/>
</joint>

<joint name="r_rod5" type="revolute">
  <origin xyz="-7e-06 0.000698 0.001475" rpy="0 0 0"/>
  <parent link="rod5_1"/>
  <child link="piston5_1"/>
  <axis xyz="-0.00416 0.427745 0.90389"/>
  <limit upper="6.283185" lower="0.0" effort="100" velocity="100"/>
</joint>

<joint name="r_rod4" type="revolute">
  <origin xyz="0.000657 -0.000387 0.001605" rpy="0 0 0"/>
  <parent link="rod4_1"/>
  <child link="piston4_1"/>
  <axis xyz="0.36999 -0.218018 0.903092"/>
  <limit upper="6.283185" lower="0.0" effort="100" velocity="100"/>
</joint>

<joint name="r_rod_xt6" type="revolute">
  <origin xyz="0.004656 0.002732 0.047133" rpy="0 0 0"/>
  <parent link="piston6_1"/>
  <child link="X6top_1"/>
  <axis xyz="-0.780129 -0.446658 -0.438059"/>
  <limit upper="0.785398" lower="-0.785398" effort="100" velocity="100"/>
</joint>

<joint name="r_rod_xt1" type="revolute">
  <origin xyz="0.036216 0.003685 0.030422" rpy="0 0 0"/>
  <parent link="piston1_1"/>
  <child link="X1top_1"/>
  <axis xyz="-0.845561 -0.483234 0.226959"/>
  <limit upper="0.785398" lower="-0.785398" effort="100" velocity="100"/>
</joint>

<joint name="r_rod_xt4" type="revolute">
  <origin xyz="0.034701 -0.020313 0.025178" rpy="0 0 0"/>
  <parent link="piston4_1"/>
  <child link="X4top_1"/>
  <axis xyz="-0.780368 0.454538 0.429443"/>
  <limit upper="0.785398" lower="-0.785398" effort="100" velocity="100"/>
</joint>

<joint name="r_rod_xt5" type="revolute">
  <origin xyz="0.021242 0.004629 0.042167" rpy="0 0 0"/>
  <parent link="piston5_1"/>
  <child link="X5top_1"/>
  <axis xyz="-0.83956 0.489554 -0.235533"/>
  <limit upper="0.785398" lower="-0.785398" effort="100" velocity="100"/>
</joint>

<joint name="r_xt1" type="revolute">
  <origin xyz="-0.008779 -0.034675 0.005815" rpy="0 0 0"/>
  <parent link="X1top_1"/>
  <child link="UJ1_1"/>
  <axis xyz="0.496404 -0.868091 0.001097"/>
  <limit upper="6.283185" lower="0.0" effort="100" velocity="100"/>
</joint>

<joint name="r_xt6" type="revolute">
  <origin xyz="-0.007111 -0.033743 -0.011142" rpy="0 0 0"/>
  <parent link="X6top_1"/>
  <child link="UJ6_1"/>
  <axis xyz="0.496404 -0.868091 0.001097"/>
  <limit upper="6.283185" lower="0.0" effort="100" velocity="100"/>
</joint>

<joint name="r_xt5" type="revolute">
  <origin xyz="-0.008441 0.03473 -0.005989" rpy="0 0 0"/>
  <parent link="X5top_1"/>
  <child link="UJ5_1"/>
  <axis xyz="0.503586 0.863945 0.000667"/>
  <limit upper="6.283185" lower="0.0" effort="100" velocity="100"/>
</joint>

<joint name="r_xt4" type="revolute">
  <origin xyz="-0.006932 0.033838 0.010968" rpy="0 0 0"/>
  <parent link="X4top_1"/>
  <child link="UJ4_1"/>
  <axis xyz="0.503586 0.863945 0.000667"/>
  <limit upper="6.283185" lower="0.0" effort="100" velocity="100"/>
</joint>

<joint name="r_rod_xt3" type="revolute">
  <origin xyz="-0.014959 0.016252 0.041985" rpy="0 0 0"/>
  <parent link="piston3_1"/>
  <child link="X3top_1"/>
  <axis xyz="-0.003623 -0.97268 -0.232123"/>
  <limit upper="0.785398" lower="-0.785398" effort="100" velocity="100"/>
</joint>

<joint name="r_xt3" type="continuous">
  <origin xyz="0.025657 -0.02491 -0.005874" rpy="0 0 0"/>
  <parent link="X3top_1"/>
  <child link="UJ3_1"/>
  <axis xyz="0.99999 -0.004146 0.001764"/>
</joint>

<joint name="r_rod_xt2" type="revolute">
  <origin xyz="-5.1e-05 0.040314 0.025009" rpy="0 0 0"/>
  <parent link="piston2_1"/>
  <child link="X2top_1"/>
  <axis xyz="-0.004501 -0.901281 0.433212"/>
  <limit upper="0.785398" lower="-0.785398" effort="100" velocity="100"/>
</joint>

<joint name="r_xt2" type="revolute">
  <origin xyz="-0.025864 -0.022876 0.011002" rpy="0 0 0"/>
  <parent link="X2top_1"/>
  <child link="UJ2_1"/>
  <axis xyz="-0.99999 0.004146 -0.001764"/>
  <limit upper="6.283185" lower="0.0" effort="100" velocity="100"/>
</joint>

<joint name="rigid1" type="fixed">
  <origin xyz="-0.012852 0.022363 0.039728" rpy="0 0 0"/>
  <parent link="UJ1_1"/>
  <child link="TOP_1"/>
</joint>

</robot>
